Workbook

Sheet WBS - Updated Product Backlog
A1: Module | B1: Subtask | C1: ID | D1: User Stories / Work Package | E1: Initial Estimation (Story Points) | F1: Sprint # | G1: Total Sprint Points | H1: Sprint 1 Done | I1: Sprint 1 Remaining | J1: Sprint 2 Done | K1: Sprint 2 Remaining | L1: Sprint 3 Done | M1: Sprint 3 Remaining | N1: Sprint 4 Done | O1: Sprint 4 Remaining | P1: Sprint 5 Done | Q1: Sprint 5 Remaining
A2: 1. Accounts & Verification | B2: Customer Registration & Login | C2: 1.1.1 | D2: Design customer registration form | E2: 4 | F2: 1 | G2: =SUMIF($F$2:$F$62,F2,$E$2:$E$62) -> 70 | H2: 4 | I2: =MAX(0,E2-H2) -> 0 | J2: 0 | K2: =MAX(0,I2-J2) -> 0 | L2: 0 | M2: =MAX(0,K2-L2) -> 0 | N2: 0 | O2: =MAX(0,M2-N2) -> 0 | P2: 0 | Q2: =MAX(0,O2-P2) -> 0
C3: 1.1.2 | D3: Implement account creation and field validation | E3: 7 | F3: 1 | H3: 7 | I3: =MAX(0,E3-H3) -> 0 | J3: 0 | K3: =MAX(0,I3-J3) -> 0 | L3: 0 | M3: =MAX(0,K3-L3) -> 0 | N3: 0 | O3: =MAX(0,M3-N3) -> 0 | P3: 0 | Q3: =MAX(0,O3-P3) -> 0
C4: 1.1.3 | D4: Store credentials securely with password hashing | E4: 5 | F4: 1 | H4: 5 | I4: =MAX(0,E4-H4) -> 0 | J4: 0 | K4: =MAX(0,I4-J4) -> 0 | L4: 0 | M4: =MAX(0,K4-L4) -> 0 | N4: 0 | O4: =MAX(0,M4-N4) -> 0 | P4: 0 | Q4: =MAX(0,O4-P4) -> 0
C5: 1.1.4 | D5: Implement login, session handling and logout | E5: 6 | F5: 1 | H5: 6 | I5: =MAX(0,E5-H5) -> 0 | J5: 0 | K5: =MAX(0,I5-J5) -> 0 | L5: 0 | M5: =MAX(0,K5-L5) -> 0 | N5: 0 | O5: =MAX(0,M5-N5) -> 0 | P5: 0 | Q5: =MAX(0,O5-P5) -> 0
B6: Profile & Access | C6: 1.2.1 | D6: Build customer profile page | E6: 4 | F6: 1 | H6: 4 | I6: =MAX(0,E6-H6) -> 0 | J6: 0 | K6: =MAX(0,I6-J6) -> 0 | L6: 0 | M6: =MAX(0,K6-L6) -> 0 | N6: 0 | O6: =MAX(0,M6-N6) -> 0 | P6: 0 | Q6: =MAX(0,O6-P6) -> 0
C7: 1.2.2 | D7: Implement profile update functionality | E7: 5 | F7: 1 | H7: 5 | I7: =MAX(0,E7-H7) -> 0 | J7: 0 | K7: =MAX(0,I7-J7) -> 0 | L7: 0 | M7: =MAX(0,K7-L7) -> 0 | N7: 0 | O7: =MAX(0,M7-N7) -> 0 | P7: 0 | Q7: =MAX(0,O7-P7) -> 0
C8: 1.2.3 | D8: Implement forgot-password and password-reset flow | E8: 5 | F8: 1 | H8: 5 | I8: =MAX(0,E8-H8) -> 0 | J8: 0 | K8: =MAX(0,I8-J8) -> 0 | L8: 0 | M8: =MAX(0,K8-L8) -> 0 | N8: 0 | O8: =MAX(0,M8-N8) -> 0 | P8: 0 | Q8: =MAX(0,O8-P8) -> 0
C9: 1.2.4 | D9: Apply customer, technician and admin role-based access | E9: 6 | F9: 1 | H9: 6 | I9: =MAX(0,E9-H9) -> 0 | J9: 0 | K9: =MAX(0,I9-J9) -> 0 | L9: 0 | M9: =MAX(0,K9-L9) -> 0 | N9: 0 | O9: =MAX(0,M9-N9) -> 0 | P9: 0 | Q9: =MAX(0,O9-P9) -> 0
B10: Technician Registration & Verification | C10: 1.3.1 | D10: Create technician service-category and working-area form | E10: 5 | F10: 1 | H10: 5 | I10: =MAX(0,E10-H10) -> 0 | J10: 0 | K10: =MAX(0,I10-J10) -> 0 | L10: 0 | M10: =MAX(0,K10-L10) -> 0 | N10: 0 | O10: =MAX(0,M10-N10) -> 0 | P10: 0 | Q10: =MAX(0,O10-P10) -> 0
C11: 1.3.2 | D11: Add NID and skill-evidence upload | E11: 8 | F11: 1 | H11: 0 | I11: =MAX(0,E11-H11) -> 8 | J11: 8 | K11: =MAX(0,I11-J11) -> 0 | L11: 0 | M11: =MAX(0,K11-L11) -> 0 | N11: 0 | O11: =MAX(0,M11-N11) -> 0 | P11: 0 | Q11: =MAX(0,O11-P11) -> 0
C12: 1.3.3 | D12: Build admin approve/reject verification workflow | E12: 6 | F12: 1 | H12: 6 | I12: =MAX(0,E12-H12) -> 0 | J12: 0 | K12: =MAX(0,I12-J12) -> 0 | L12: 0 | M12: =MAX(0,K12-L12) -> 0 | N12: 0 | O12: =MAX(0,M12-N12) -> 0 | P12: 0 | Q12: =MAX(0,O12-P12) -> 0
C13: 1.3.4 | D13: Show verification status and verified badge | E13: 4 | F13: 1 | H13: 4 | I13: =MAX(0,E13-H13) -> 0 | J13: 0 | K13: =MAX(0,I13-J13) -> 0 | L13: 0 | M13: =MAX(0,K13-L13) -> 0 | N13: 0 | O13: =MAX(0,M13-N13) -> 0 | P13: 0 | Q13: =MAX(0,O13-P13) -> 0
A14: 2. Location-Based Discovery | B14: Location Capture | C14: 2.1.1 | D14: Request browser location permission and capture coordinates | E14: 5 | F14: 1 | H14: 5 | I14: =MAX(0,E14-H14) -> 0 | J14: 0 | K14: =MAX(0,I14-J14) -> 0 | L14: 0 | M14: =MAX(0,K14-L14) -> 0 | N14: 0 | O14: =MAX(0,M14-N14) -> 0 | P14: 0 | Q14: =MAX(0,O14-P14) -> 0
C15: 2.1.2 | D15: Add manual location and area input | E15: 5 | F15: 2 | G15: =SUMIF($F$2:$F$62,F15,$E$2:$E$62) -> 70 | H15: 0 | I15: =MAX(0,E15-H15) -> 5 | J15: 0 | K15: =MAX(0,I15-J15) -> 5 | L15: 5 | M15: =MAX(0,K15-L15) -> 0 | N15: 0 | O15: =MAX(0,M15-N15) -> 0 | P15: 0 | Q15: =MAX(0,O15-P15) -> 0
C16: 2.1.3 | D16: Geocode, normalize and save the selected location | E16: 8 | F16: 2 | H16: 0 | I16: =MAX(0,E16-H16) -> 8 | J16: 8 | K16: =MAX(0,I16-J16) -> 0 | L16: 0 | M16: =MAX(0,K16-L16) -> 0 | N16: 0 | O16: =MAX(0,M16-N16) -> 0 | P16: 0 | Q16: =MAX(0,O16-P16) -> 0
B17: Nearby Technician Discovery | C17: 2.2.1 | D17: Query verified technicians by service category and location | E17: 8 | F17: 2 | H17: 0 | I17: =MAX(0,E17-H17) -> 8 | J17: 8 | K17: =MAX(0,I17-J17) -> 0 | L17: 0 | M17: =MAX(0,K17-L17) -> 0 | N17: 0 | O17: =MAX(0,M17-N17) -> 0 | P17: 0 | Q17: =MAX(0,O17-P17) -> 0
C18: 2.2.2 | D18: Calculate distance/radius and rank nearby results | E18: 8 | F18: 2 | H18: 0 | I18: =MAX(0,E18-H18) -> 8 | J18: 8 | K18: =MAX(0,I18-J18) -> 0 | L18: 0 | M18: =MAX(0,K18-L18) -> 0 | N18: 0 | O18: =MAX(0,M18-N18) -> 0 | P18: 0 | Q18: =MAX(0,O18-P18) -> 0
C19: 2.2.3 | D19: Filter and sort by distance, rating and availability | E19: 7 | F19: 2 | H19: 0 | I19: =MAX(0,E19-H19) -> 7 | J19: 7 | K19: =MAX(0,I19-J19) -> 0 | L19: 0 | M19: =MAX(0,K19-L19) -> 0 | N19: 0 | O19: =MAX(0,M19-N19) -> 0 | P19: 0 | Q19: =MAX(0,O19-P19) -> 0
C20: 2.2.4 | D20: Build map/list results with technician profile links | E20: 9 | F20: 2 | H20: 0 | I20: =MAX(0,E20-H20) -> 9 | J20: 9 | K20: =MAX(0,I20-J20) -> 0 | L20: 0 | M20: =MAX(0,K20-L20) -> 0 | N20: 0 | O20: =MAX(0,M20-N20) -> 0 | P20: 0 | Q20: =MAX(0,O20-P20) -> 0
B21: Reliability & Fallback | C21: 2.3.1 | D21: Handle location-permission and map/API errors | E21: 5 | F21: 2 | H21: 0 | I21: =MAX(0,E21-H21) -> 5 | J21: 5 | K21: =MAX(0,I21-J21) -> 0 | L21: 0 | M21: =MAX(0,K21-L21) -> 0 | N21: 0 | O21: =MAX(0,M21-N21) -> 0 | P21: 0 | Q21: =MAX(0,O21-P21) -> 0
C22: 2.3.2 | D22: Implement area/service fallback when map results fail | E22: 6 | F22: 2 | H22: 0 | I22: =MAX(0,E22-H22) -> 6 | J22: 6 | K22: =MAX(0,I22-J22) -> 0 | L22: 0 | M22: =MAX(0,K22-L22) -> 0 | N22: 0 | O22: =MAX(0,M22-N22) -> 0 | P22: 0 | Q22: =MAX(0,O22-P22) -> 0
C23: 2.3.3 | D23: Test multiple Dhaka locations, empty states and edge cases | E23: 5 | F23: 2 | H23: 0 | I23: =MAX(0,E23-H23) -> 5 | J23: 5 | K23: =MAX(0,I23-J23) -> 0 | L23: 0 | M23: =MAX(0,K23-L23) -> 0 | N23: 0 | O23: =MAX(0,M23-N23) -> 0 | P23: 0 | Q23: =MAX(0,O23-P23) -> 0
C24: 2.3.4 | D24: Limit and handle stored location data safely | E24: 4 | F24: 2 | H24: 0 | I24: =MAX(0,E24-H24) -> 4 | J24: 4 | K24: =MAX(0,I24-J24) -> 0 | L24: 0 | M24: =MAX(0,K24-L24) -> 0 | N24: 0 | O24: =MAX(0,M24-N24) -> 0 | P24: 0 | Q24: =MAX(0,O24-P24) -> 0
A25: 3. Service Request, Booking & Tracking | B25: Repair Request Creation | C25: 3.1.1 | D25: Build normal repair-request form | E25: 5 | F25: 2 | H25: 0 | I25: =MAX(0,E25-H25) -> 5 | J25: 0 | K25: =MAX(0,I25-J25) -> 5 | L25: 5 | M25: =MAX(0,K25-L25) -> 0 | N25: 0 | O25: =MAX(0,M25-N25) -> 0 | P25: 0 | Q25: =MAX(0,O25-P25) -> 0
C26: 3.1.2 | D26: Add issue-photo attachment | E26: 5 | F26: 3 | G26: =SUMIF($F$2:$F$62,F26,$E$2:$E$62) -> 70 | H26: 0 | I26: =MAX(0,E26-H26) -> 5 | J26: 0 | K26: =MAX(0,I26-J26) -> 5 | L26: 5 | M26: =MAX(0,K26-L26) -> 0 | N26: 0 | O26: =MAX(0,M26-N26) -> 0 | P26: 0 | Q26: =MAX(0,O26-P26) -> 0
C27: 3.1.3 | D27: Validate service category, issue details and required fields | E27: 6 | F27: 3 | H27: 0 | I27: =MAX(0,E27-H27) -> 6 | J27: 0 | K27: =MAX(0,I27-J27) -> 6 | L27: 6 | M27: =MAX(0,K27-L27) -> 0 | N27: 0 | O27: =MAX(0,M27-N27) -> 0 | P27: 0 | Q27: =MAX(0,O27-P27) -> 0
C28: 3.1.4 | D28: Save request and generate a unique request ID | E28: 6 | F28: 3 | H28: 0 | I28: =MAX(0,E28-H28) -> 6 | J28: 0 | K28: =MAX(0,I28-J28) -> 6 | L28: 6 | M28: =MAX(0,K28-L28) -> 0 | N28: 0 | O28: =MAX(0,M28-N28) -> 0 | P28: 0 | Q28: =MAX(0,O28-P28) -> 0
B29: Booking & Technician Response | C29: 3.2.1 | D29: Build technician incoming-request queue | E29: 5 | F29: 3 | H29: 0 | I29: =MAX(0,E29-H29) -> 5 | J29: 0 | K29: =MAX(0,I29-J29) -> 5 | L29: 5 | M29: =MAX(0,K29-L29) -> 0 | N29: 0 | O29: =MAX(0,M29-N29) -> 0 | P29: 0 | Q29: =MAX(0,O29-P29) -> 0
C30: 3.2.2 | D30: Implement accept/reject response workflow | E30: 6 | F30: 3 | H30: 0 | I30: =MAX(0,E30-H30) -> 6 | J30: 0 | K30: =MAX(0,I30-J30) -> 6 | L30: 6 | M30: =MAX(0,K30-L30) -> 0 | N30: 0 | O30: =MAX(0,M30-N30) -> 0 | P30: 0 | Q30: =MAX(0,O30-P30) -> 0
C31: 3.2.3 | D31: Send customer confirmation and request notification | E31: 7 | F31: 3 | H31: 0 | I31: =MAX(0,E31-H31) -> 7 | J31: 0 | K31: =MAX(0,I31-J31) -> 7 | L31: 7 | M31: =MAX(0,K31-L31) -> 0 | N31: 0 | O31: =MAX(0,M31-N31) -> 0 | P31: 0 | Q31: =MAX(0,O31-P31) -> 0
B32: Status, Emergency & Estimate | C32: 3.3.1 | D32: Implement request status transitions from sent to completed | E32: 7 | F32: 3 | H32: 0 | I32: =MAX(0,E32-H32) -> 7 | J32: 0 | K32: =MAX(0,I32-J32) -> 7 | L32: 7 | M32: =MAX(0,K32-L32) -> 0 | N32: 0 | O32: =MAX(0,M32-N32) -> 0 | P32: 0 | Q32: =MAX(0,O32-P32) -> 0
C33: 3.3.2 | D33: Build customer status timeline and tracking view | E33: 5 | F33: 3 | H33: 0 | I33: =MAX(0,E33-H33) -> 5 | J33: 0 | K33: =MAX(0,I33-J33) -> 5 | L33: 5 | M33: =MAX(0,K33-L33) -> 0 | N33: 0 | O33: =MAX(0,M33-N33) -> 0 | P33: 0 | Q33: =MAX(0,O33-P33) -> 0
C34: 3.3.3 | D34: Add controlled emergency/urgent request flag | E34: 6 | F34: 3 | H34: 0 | I34: =MAX(0,E34-H34) -> 6 | J34: 0 | K34: =MAX(0,I34-J34) -> 6 | L34: 6 | M34: =MAX(0,K34-L34) -> 0 | N34: 0 | O34: =MAX(0,M34-N34) -> 0 | P34: 0 | Q34: =MAX(0,O34-P34) -> 0
C35: 3.3.4 | D35: Display estimated price/time and booking confirmation | E35: 6 | F35: 3 | H35: 0 | I35: =MAX(0,E35-H35) -> 6 | J35: 0 | K35: =MAX(0,I35-J35) -> 6 | L35: 6 | M35: =MAX(0,K35-L35) -> 0 | N35: 0 | O35: =MAX(0,M35-N35) -> 0 | P35: 0 | Q35: =MAX(0,O35-P35) -> 0
C36: 3.3.5 | D36: Notify users about important request-status changes | E36: 6 | F36: 3 | H36: 0 | I36: =MAX(0,E36-H36) -> 6 | J36: 0 | K36: =MAX(0,I36-J36) -> 6 | L36: 6 | M36: =MAX(0,K36-L36) -> 0 | N36: 0 | O36: =MAX(0,M36-N36) -> 0 | P36: 0 | Q36: =MAX(0,O36-P36) -> 0
A37: 4. Trust, Safety & Feedback | B37: Ratings & Service History | C37: 4.1.1 | D37: Enable rating only after a completed service | E37: 5 | F37: 3 | H37: 0 | I37: =MAX(0,E37-H37) -> 5 | J37: 0 | K37: =MAX(0,I37-J37) -> 5 | L37: 5 | M37: =MAX(0,K37-L37) -> 0 | N37: 0 | O37: =MAX(0,M37-N37) -> 0 | P37: 0 | Q37: =MAX(0,O37-P37) -> 0
C38: 4.1.2 | D38: Validate and save 1-5 star rating | E38: 5 | F38: 4 | G38: =SUMIF($F$2:$F$62,F38,$E$2:$E$62) -> 70 | H38: 0 | I38: =MAX(0,E38-H38) -> 5 | J38: 0 | K38: =MAX(0,I38-J38) -> 5 | L38: 0 | M38: =MAX(0,K38-L38) -> 5 | N38: 5 | O38: =MAX(0,M38-N38) -> 0 | P38: 0 | Q38: =MAX(0,O38-P38) -> 0
C39: 4.1.3 | D39: Submit and display written review | E39: 5 | F39: 4 | H39: 0 | I39: =MAX(0,E39-H39) -> 5 | J39: 0 | K39: =MAX(0,I39-J39) -> 5 | L39: 0 | M39: =MAX(0,K39-L39) -> 5 | N39: 5 | O39: =MAX(0,M39-N39) -> 0 | P39: 0 | Q39: =MAX(0,O39-P39) -> 0
C40: 4.1.4 | D40: Show customer service history | E40: 5 | F40: 4 | H40: 0 | I40: =MAX(0,E40-H40) -> 5 | J40: 0 | K40: =MAX(0,I40-J40) -> 5 | L40: 0 | M40: =MAX(0,K40-L40) -> 5 | N40: 5 | O40: =MAX(0,M40-N40) -> 0 | P40: 0 | Q40: =MAX(0,O40-P40) -> 0
...

Sheet Sprint wise spent
B2: Sprint 5 | C2: Sprint 5 | D2: Sprint 5 | E2: Sprint 5 | F2: Sprint 5 | G2: Sprint 5 | I2: Sprint 4 | J2: Sprint 4 | K2: Sprint 4 | L2: Sprint 4 | M2: Sprint 4 | O2: Sprint 3 | P2: Sprint 3 | Q2: Sprint 3 | R2: Sprint 3 | S2: Sprint 3 | U2: Sprint 2 | V2: Sprint 2 | W2: Sprint 2 | X2: Sprint 2 | Y2: Sprint 2 | AA2: Sprint 1 | AB2: Sprint 1 | AC2: Sprint 1 | AD2: Sprint 1 | AE2: Sprint 1
B3: Person | C3: Level | D3: Weighted | E3: Allocation | F3: Cost | G3: Jira Hour | I3: Level | J3: Weighted | K3: Allocation | L3: Cost | M3: Jira Hour | O3: Level | P3: Weighted | Q3: Allocation | R3: Cost | S3: Jira Hour | U3: Level | V3: Weighted | W3: Allocation | X3: Cost | Y3: Jira Hour | AA3: Level | AB3: Weighted | AC3: Allocation | AD3: Cost | AE3: Jira Hour
B4: Md. Jubayer Hasan | C4: Lead | D4: 2 | E4: 0.4 | F4: =D4*E4 -> 0.8 | G4: =E4*8*Config!$B$11 -> 32 | I4: Lead | J4: 2 | K4: 0.3 | L4: =J4*K4 -> 0.6 | M4: =K4*8*Config!$B$11 -> 24 | O4: Lead | P4: 2 | Q4: 0.3 | R4: =P4*Q4 -> 0.6 | S4: =Q4*8*Config!$B$11 -> 24 | U4: Lead | V4: 2 | W4: 0.3 | X4: =V4*W4 -> 0.6 | Y4: =W4*8*Config!$B$11 -> 24 | AA4: Lead | AB4: 2 | AC4: 0.3 | AD4: =AB4*AC4 -> 0.6 | AE4: =AC4*8*Config!$B$11 -> 24
B5: Fahim Ahmed | C5: Senior | D5: 1.3 | E5: 0.5 | F5: =D5*E5 -> 0.65 | G5: =E5*8*Config!$B$11 -> 40 | I5: Senior | J5: 1.3 | K5: 0.5 | L5: =J5*K5 -> 0.65 | M5: =K5*8*Config!$B$11 -> 40 | O5: Senior | P5: 1.3 | Q5: 0.6 | R5: =P5*Q5 -> 0.78 | S5: =Q5*8*Config!$B$11 -> 48 | U5: Senior | V5: 1.3 | W5: 0.6 | X5: =V5*W5 -> 0.78 | Y5: =W5*8*Config!$B$11 -> 48 | AA5: Senior | AB5: 1.3 | AC5: 0.5 | AD5: =AB5*AC5 -> 0.65 | AE5: =AC5*8*Config!$B$11 -> 40
B6: Sheikh Md Rakibul Hasan | C6: Mid | D6: 1 | E6: 0.3 | F6: =D6*E6 -> 0.3 | G6: =E6*8*Config!$B$11 -> 24 | I6: Mid | J6: 1 | K6: 0.3 | L6: =J6*K6 -> 0.3 | M6: =K6*8*Config!$B$11 -> 24 | O6: Mid | P6: 1 | Q6: 0.3 | R6: =P6*Q6 -> 0.3 | S6: =Q6*8*Config!$B$11 -> 24 | U6: Mid | V6: 1 | W6: 0.3 | X6: =V6*W6 -> 0.3 | Y6: =W6*8*Config!$B$11 -> 24 | AA6: Mid | AB6: 1 | AC6: 0.3 | AD6: =AB6*AC6 -> 0.3 | AE6: =AC6*8*Config!$B$11 -> 24
B7: Pallob Nath | C7: Junior | D7: 0.7 | E7: 0.4 | F7: =D7*E7 -> 0.28 | G7: =E7*8*Config!$B$11 -> 32 | I7: Junior | J7: 0.7 | K7: 0.3 | L7: =J7*K7 -> 0.21 | M7: =K7*8*Config!$B$11 -> 24 | O7: Junior | P7: 0.7 | Q7: 0.3 | R7: =P7*Q7 -> 0.21 | S7: =Q7*8*Config!$B$11 -> 24 | U7: Junior | V7: 0.7 | W7: 0.2 | X7: =V7*W7 -> 0.14 | Y7: =W7*8*Config!$B$11 -> 16 | AA7: Junior | AB7: 0.7 | AC7: 0.2 | AD7: =AB7*AC7 -> 0.14 | AE7: =AC7*8*Config!$B$11 -> 16
B8: K.M. Sakif Muhtasim | C8: Mid | D8: 1 | E8: 0.2 | F8: =D8*E8 -> 0.2 | G8: =E8*8*Config!$B$11 -> 16 | I8: Mid | J8: 1 | K8: 0.2 | L8: =J8*K8 -> 0.2 | M8: =K8*8*Config!$B$11 -> 16 | O8: Mid | P8: 1 | Q8: 0.2 | R8: =P8*Q8 -> 0.2 | S8: =Q8*8*Config!$B$11 -> 16 | U8: Mid | V8: 1 | W8: 0.3 | X8: =V8*W8 -> 0.3 | Y8: =W8*8*Config!$B$11 -> 24 | AA8: Mid | AB8: 1 | AC8: 0.3 | AD8: =AB8*AC8 -> 0.3 | AE8: =AC8*8*Config!$B$11 -> 24
B9: TOTAL | C9: TOTAL | D9: TOTAL | E9: =SUM(E4:E8) -> 1.8 | F9: =SUM(F4:F8) -> 2.23 | G9: =SUM(G4:G8) -> 144 | I9: TOTAL | J9: TOTAL | K9: =SUM(K4:K8) -> 1.6 | L9: =SUM(L4:L8) -> 1.96 | M9: =SUM(M4:M8) -> 128 | O9: TOTAL | P9: TOTAL | Q9: =SUM(Q4:Q8) -> 1.7 | R9: =SUM(R4:R8) -> 2.09 | S9: =SUM(S4:S8) -> 136 | U9: TOTAL | V9: TOTAL | W9: =SUM(W4:W8) -> 1.7 | X9: =SUM(X4:X8) -> 2.12 | Y9: =SUM(Y4:Y8) -> 136 | AA9: TOTAL | AB9: TOTAL | AC9: =SUM(AC4:AC8) -> 1.6 | AD9: =SUM(AD4:AD8) -> 1.99 | AE9: =SUM(AE4:AE8) -> 128
B10: Man-weeks spent | C10: Man-weeks spent | D10: Man-weeks spent | E10: Man-weeks spent | F10: =F9*2 -> 4.46 | I10: Man-weeks spent | J10: Man-weeks spent | K10: Man-weeks spent | L10: =L9*2 -> 3.92 | O10: Man-weeks spent | P10: Man-weeks spent | Q10: Man-weeks spent | R10: =R9*2 -> 4.18 | U10: Man-weeks spent | V10: Man-weeks spent | W10: Man-weeks spent | X10: =X9*2 -> 4.24 | AA10: Man-weeks spent | AB10: Man-weeks spent | AC10: Man-weeks spent | AD10: =AD9*2 -> 3.98
B11: Weighted man-days spent | C11: Weighted man-days spent | D11: Weighted man-days spent | E11: Weighted man-days spent | F11: =F10*5 -> 22.3 | I11: Weighted man-days spent | J11: Weighted man-days spent | K11: Weighted man-days spent | L11: =L10*5 -> 19.6 | O11: Weighted man-days spent | P11: Weighted man-days spent | Q11: Weighted man-days spent | R11: =R10*5 -> 20.9 | U11: Weighted man-days spent | V11: Weighted man-days spent | W11: Weighted man-days spent | X11: =X10*5 -> 21.2 | AA11: Weighted man-days spent | AB11: Weighted man-days spent | AC11: Weighted man-days spent | AD11: =AD10*5 -> 19.9
B12: Actual labor cost cumulative (BDT) | C12: Actual labor cost cumulative (BDT) | D12: Actual labor cost cumulative (BDT) | E12: Actual labor cost cumulative (BDT) | F12: =SUM(AD11,X11,R11,L11,F11)*Config!$B$12 -> 207800 | I12: Actual labor cost cumulative (BDT) | J12: Actual labor cost cumulative (BDT) | K12: Actual labor cost cumulative (BDT) | L12: =SUM(AD11,X11,R11,L11)*Config!$B$12 -> 163200 | O12: Actual labor cost cumulative (BDT) | P12: Actual labor cost cumulative (BDT) | Q12: Actual labor cost cumulative (BDT) | R12: =SUM(AD11,X11,R11)*Config!$B$12 -> 124000 | U12: Actual labor cost cumulative (BDT) | V12: Actual labor cost cumulative (BDT) | W12: Actual labor cost cumulative (BDT) | X12: =SUM(AD11,X11)*Config!$B$12 -> 82200 | AA12: Actual labor cost cumulative (BDT) | AB12: Actual labor cost cumulative (BDT) | AC12: Actual labor cost cumulative (BDT) | AD12: =SUM(AD11)*Config!$B$12 -> 39800
B14: Earned Value (Points) | C14: Earned Value (Points) | D14: Earned Value (Points) | E14: Earned Value (Points) | F14: ='WBS - Updated Product Backlog'!$P$63 -> 70 | I14: Earned Value (Points) | J14: Earned Value (Points) | K14: Earned Value (Points) | L14: ='WBS - Updated Product Backlog'!$N$63 -> 70 | O14: Earned Value (Points) | P14: Earned Value (Points) | Q14: Earned Value (Points) | R14: ='WBS - Updated Product Backlog'!$L$63 -> 80 | U14: Earned Value (Points) | V14: Earned Value (Points) | W14: Earned Value (Points) | X14: ='WBS - Updated Product Backlog'!$J$63 -> 68 | AA14: Earned Value (Points) | AB14: Earned Value (Points) | AC14: Earned Value (Points) | AD14: ='WBS - Updated Product Backlog'!$H$63 -> 62
B15: Cumulative Earned Value (Points) | C15: Cumulative Earned Value (Points) | D15: Cumulative Earned Value (Points) | E15: Cumulative Earned Value (Points) | F15: =SUM('WBS - Updated Product Backlog'!$H$63,'WBS - Updated Product Backlog'!$J$63,'WBS - Updated Product Backlog'!$L$63,'WBS - Updated Product Backlog'!$N$63,'WBS - Updated Product Backlog'!$P$63) -> 350 | G15: =F15/'WBS - Updated Product Backlog'!$E$63 -> 1 | I15: Cumulative Earned Value (Points) | J15: Cumulative Earned Value (Points) | K15: Cumulative Earned Value (Points) | L15: =SUM('WBS - Updated Product Backlog'!$H$63,'WBS - Updated Product Backlog'!$J$63,'WBS - Updated Product Backlog'!$L$63,'WBS - Updated Product Backlog'!$N$63) -> 280 | M15: =L15/'WBS - Updated Product Backlog'!$E$63 -> 0.8 | O15: Cumulative Earned Value (Points) | P15: Cumulative Earned Value (Points) | Q15: Cumulative Earned Value (Points) | R15: =SUM('WBS - Updated Product Backlog'!$H$63,'WBS - Updated Product Backlog'!$J$63,'WBS - Updated Product Backlog'!$L$63) -> 210 | S15: =R15/'WBS - Updated Product Backlog'!$E$63 -> 0.6 | U15: Cumulative Earned Value (Points) | V15: Cumulative Earned Value (Points) | W15: Cumulative Earned Value (Points) | X15: =SUM('WBS - Updated Product Backlog'!$H$63,'WBS - Updated Product Backlog'!$J$63) -> 130 | Y15: =X15/'WBS - Updated Product Backlog'!$E$63 -> 0.37142857 | AA15: Cumulative Earned Value (Points) | AB15: Cumulative Earned Value (Points) | AC15: Cumulative Earned Value (Points) | AD15: =SUM('WBS - Updated Product Backlog'!$H$63) -> 62 | AE15: =AD15/'WBS - Updated Product Backlog'!$E$63 -> 0.17714286
B16: Labor Cost Variance (BDT) | C16: Labor Cost Variance (BDT) | D16: Labor Cost Variance (BDT) | E16: Labor Cost Variance (BDT) | F16: =F15/'WBS - Updated Product Backlog'!$E$63*$F$12-F12 -> 0 | I16: Labor Cost Variance (BDT) | J16: Labor Cost Variance (BDT) | K16: Labor Cost Variance (BDT) | L16: =L15/'WBS - Updated Product Backlog'!$E$63*$F$12-L12 -> 3040 | O16: Labor Cost Variance (BDT) | P16: Labor Cost Variance (BDT) | Q16: Labor Cost Variance (BDT) | R16: =R15/'WBS - Updated Product Backlog'!$E$63*$F$12-R12 -> 680 | U16: Labor Cost Variance (BDT) | V16: Labor Cost Variance (BDT) | W16: Labor Cost Variance (BDT) | X16: =X15/'WBS - Updated Product Backlog'!$E$63*$F$12-X12 -> -5017.1429 | AA16: Labor Cost Variance (BDT) | AB16: Labor Cost Variance (BDT) | AC16: Labor Cost Variance (BDT) | AD16: =AD15/'WBS - Updated Product Backlog'!$E$63*$F$12-AD12 -> -2989.7143
B18: Planned Value (Points) | C18: Planned Value (Points) | D18: Planned Value (Points) | E18: Planned Value (Points) | F18: =SUMIF('WBS - Updated Product Backlog'!$F$2:$F$62,5,'WBS - Updated Product Backlog'!$E$2:$E$62) -> 70 | I18: Planned Value (Points) | J18: Planned Value (Points) | K18: Planned Value (Points) | L18: =SUMIF('WBS - Updated Product Backlog'!$F$2:$F$62,4,'WBS - Updated Product Backlog'!$E$2:$E$62) -> 70 | O18: Planned Value (Points) | P18: Planned Value (Points) | Q18: Planned Value (Points) | R18: =SUMIF('WBS - Updated Product Backlog'!$F$2:$F$62,3,'WBS - Updated Product Backlog'!$E$2:$E$62) -> 70 | U18: Planned Value (Points) | V18: Planned Value (Points) | W18: Planned Value (Points) | X18: =SUMIF('WBS - Updated Product Backlog'!$F$2:$F$62,2,'WBS - Updated Product Backlog'!$E$2:$E$62) -> 70 | AA18: Planned Value (Points) | AB18: Planned Value (Points) | AC18: Planned Value (Points) | AD18: =SUMIF('WBS - Updated Product Backlog'!$F$2:$F$62,1,'WBS - Updated Product Backlog'!$E$2:$E$62) -> 70
B19: Cumulative PV (Points) | C19: Cumulative PV (Points) | D19: Cumulative PV (Points) | E19: Cumulative PV (Points) | F19: =SUM(AD18,X18,R18,L18,F18) -> 350 | I19: Cumulative PV (Points) | J19: Cumulative PV (Points) | K19: Cumulative PV (Points) | L19: =SUM(AD18,X18,R18,L18) -> 280 | O19: Cumulative PV (Points) | P19: Cumulative PV (Points) | Q19: Cumulative PV (Points) | R19: =SUM(AD18,X18,R18) -> 210 | U19: Cumulative PV (Points) | V19: Cumulative PV (Points) | W19: Cumulative PV (Points) | X19: =SUM(AD18,X18) -> 140 | AA19: Cumulative PV (Points) | AB19: Cumulative PV (Points) | AC19: Cumulative PV (Points) | AD19: =SUM(AD18) -> 70
B20: Schedule Variance (Points) | C20: Schedule Variance (Points) | D20: Schedule Variance (Points) | E20: Schedule Variance (Points) | F20: =F15-F19 -> 0 | I20: Schedule Variance (Points) | J20: Schedule Variance (Points) | K20: Schedule Variance (Points) | L20: =L15-L19 -> 0 | O20: Schedule Variance (Points) | P20: Schedule Variance (Points) | Q20: Schedule Variance (Points) | R20: =R15-R19 -> 0 | U20: Schedule Variance (Points) | V20: Schedule Variance (Points) | W20: Schedule Variance (Points) | X20: =X15-X19 -> -10 | AA20: Schedule Variance (Points) | AB20: Schedule Variance (Points) | AC20: Schedule Variance (Points) | AD20: =AD15-AD19 -> -8
B21: Schedule status | C21: Schedule status | D21: Schedule status | E21: Schedule status | F21: =IF(F20=0,"On Schedule",IF(F20<0,"Behind Schedule","Ahead of Schedule")) -> On Schedule | I21: Schedule status | J21: Schedule status | K21: Schedule status | L21: =IF(L20=0,"On Schedule",IF(L20<0,"Behind Schedule","Ahead of Schedule")) -> On Schedule | O21: Schedule status | P21: Schedule status | Q21: Schedule status | R21: =IF(R20=0,"On Schedule",IF(R20<0,"Behind Schedule","Ahead of Schedule")) -> On Schedule | U21: Schedule status | V21: Schedule status | W21: Schedule status | X21: =IF(X20=0,"On Schedule",IF(X20<0,"Behind Schedule","Ahead of Schedule")) -> Behind Schedule | AA21: Schedule status | AB21: Schedule status | AC21: Schedule status | AD21: =IF(AD20=0,"On Schedule",IF(AD20<0,"Behind Schedule","Ahead of Schedule")) -> Behind Schedule
B23: Sprint 5 Completed Work | C23: Sprint 5 Completed Work | D23: Sprint 5 Completed Work | E23: Sprint 5 Completed Work | F23: Sprint 5 Completed Work | G23: Sprint 5 Completed Work | I23: Sprint 4 Completed Work | J23: Sprint 4 Completed Work | K23: Sprint 4 Completed Work | L23: Sprint 4 Completed Work | M23: Sprint 4 Completed Work | O23: Sprint 3 Completed Work | P23: Sprint 3 Completed Work | Q23: Sprint 3 Completed Work | R23: Sprint 3 Completed Work | S23: Sprint 3 Completed Work | U23: Sprint 2 Completed Work | V23: Sprint 2 Completed Work | W23: Sprint 2 Completed Work | X23: Sprint 2 Completed Work | Y23: Sprint 2 Completed Work | AA23: Sprint 1 Completed Work | AB23: Sprint 1 Completed Work | AC23: Sprint 1 Completed Work | AD23: Sprint 1 Completed Work | AE23: Sprint 1 Completed Work
B24: Work Package | C24: Work Package | D24: Work Package | E24: Work Package | F24: Work Package | G24: Done | I24: Work Package | J24: Work Package | K24: Work Package | L24: Work Package | M24: Done | O24: Work Package | P24: Work Package | Q24: Work Package | R24: Work Package | S24: Done | U24: Work Package | V24: Work Package | W24: Work Package | X24: Work Package | Y24: Done | AA24: Work Package | AB24: Work Package | AC24: Work Package | AD24: Work Package | AE24: Done
B25: ='WBS - Updated Product Backlog'!$C$51&" "&'WBS - Updated Product Backlog'!$D$51&"" -> 5.1.3 Manage service categories | G25: ='WBS - Updated Product Backlog'!$P$51 -> 6 | I25: ='WBS - Updated Product Backlog'!$C$38&" "&'WBS - Updated Product Backlog'!$D$38&"" -> 4.1.2 Validate and save 1-5 star rating | M25: ='WBS - Updated Product Backlog'!$N$38 -> 5 | O25: ='WBS - Updated Product Backlog'!$C$15&" "&'WBS - Updated Product Backlog'!$D$15&" [Carryover]" -> 2.1.2 Add manual location and area input [Carryover] | S25: ='WBS - Updated Product Backlog'!$L$15 -> 5 | U25: ='WBS - Updated Product Backlog'!$C$11&" "&'WBS - Updated Product Backlog'!$D$11&" [Carryover]" -> 1.3.2 Add NID and skill-evidence upload [Carryover] | Y25: ='WBS - Updated Product Backlog'!$J$11 -> 8 | AA25: ='WBS - Updated Product Backlog'!$C$2&" "&'WBS - Updated Product Backlog'!$D$2&"" -> 1.1.1 Design customer registration form | AE25: ='WBS - Updated Product Backlog'!$H$2 -> 4
B26: ='WBS - Updated Product Backlog'!$C$52&" "&'WBS - Updated Product Backlog'!$D$52&"" -> 5.1.4 Manage service coverage areas | G26: ='WBS - Updated Product Backlog'!$P$52 -> 4 | I26: ='WBS - Updated Product Backlog'!$C$39&" "&'WBS - Updated Product Backlog'!$D$39&"" -> 4.1.3 Submit and display written review | M26: ='WBS - Updated Product Backlog'!$N$39 -> 5 | O26: ='WBS - Updated Product Backlog'!$C$25&" "&'WBS - Updated Product Backlog'!$D$25&" [Carryover]" -> 3.1.1 Build normal repair-request form [Carryover] | S26: ='WBS - Updated Product Backlog'!$L$25 -> 5 | U26: ='WBS - Updated Product Backlog'!$C$16&" "&'WBS - Updated Product Backlog'!$D$16&"" -> 2.1.3 Geocode, normalize and save the selected location | Y26: ='WBS - Updated Product Backlog'!$J$16 -> 8 | AA26: ='WBS - Updated Product Backlog'!$C$3&" "&'WBS - Updated Product Backlog'!$D$3&"" -> 1.1.2 Implement account creation and field validation | AE26: ='WBS - Updated Product Backlog'!$H$3 -> 7
B27: ='WBS - Updated Product Backlog'!$C$53&" "&'WBS - Updated Product Backlog'!$D$53&"" -> 5.1.5 Verify, suspend or remove technician accounts | G27: ='WBS - Updated Product Backlog'!$P$53 -> 5 | I27: ='WBS - Updated Product Backlog'!$C$40&" "&'WBS - Updated Product Backlog'!$D$40&"" -> 4.1.4 Show customer service history | M27: ='WBS - Updated Product Backlog'!$N$40 -> 5 | O27: ='WBS - Updated Product Backlog'!$C$26&" "&'WBS - Updated Product Backlog'!$D$26&"" -> 3.1.2 Add issue-photo attachment | S27: ='WBS - Updated Product Backlog'!$L$26 -> 5 | U27: ='WBS - Updated Product Backlog'!$C$17&" "&'WBS - Updated Product Backlog'!$D$17&"" -> 2.2.1 Query verified technicians by service category and location | Y27: ='WBS - Updated Product Backlog'!$J$17 -> 8 | AA27: ='WBS - Updated Product Backlog'!$C$4&" "&'WBS - Updated Product Backlog'!$D$4&"" -> 1.1.3 Store credentials securely with password hashing | AE27: ='WBS - Updated Product Backlog'!$H$4 -> 5
B28: ='WBS - Updated Product Backlog'!$C$54&" "&'WBS - Updated Product Backlog'!$D$54&"" -> 5.2.1 Implement dispute-resolution workflow | G28: ='WBS - Updated Product Backlog'!$P$54 -> 6 | I28: ='WBS - Updated Product Backlog'!$C$41&" "&'WBS - Updated Product Backlog'!$D$41&"" -> 4.2.1 Submit complaint for a completed service | M28: ='WBS - Updated Product Backlog'!$N$41 -> 5 | O28: ='WBS - Updated Product Backlog'!$C$27&" "&'WBS - Updated Product Backlog'!$D$27&"" -> 3.1.3 Validate service category, issue details and required fields | S28: ='WBS - Updated Product Backlog'!$L$27 -> 6 | U28: ='WBS - Updated Product Backlog'!$C$18&" "&'WBS - Updated Product Backlog'!$D$18&"" -> 2.2.2 Calculate distance/radius and rank nearby results | Y28: ='WBS - Updated Product Backlog'!$J$18 -> 8 | AA28: ='WBS - Updated Product Backlog'!$C$5&" "&'WBS - Updated Product Backlog'!$D$5&"" -> 1.1.4 Implement login, session handling and logout | AE28: ='WBS - Updated Product Backlog'!$H$5 -> 6
B29: ='WBS - Updated Product Backlog'!$C$55&" "&'WBS - Updated Product Backlog'!$D$55&"" -> 5.2.2 Add important platform-activity and admin audit monitoring | G29: ='WBS - Updated Product Backlog'!$P$55 -> 5 | I29: ='WBS - Updated Product Backlog'!$C$42&" "&'WBS - Updated Product Backlog'!$D$42&"" -> 4.2.2 Report a safety concern for admin review | M29: ='WBS - Updated Product Backlog'!$N$42 -> 5 | O29: ='WBS - Updated Product Backlog'!$C$28&" "&'WBS - Updated Product Backlog'!$D$28&"" -> 3.1.4 Save request and generate a unique request ID | S29: ='WBS - Updated Product Backlog'!$L$28 -> 6 | U29: ='WBS - Updated Product Backlog'!$C$19&" "&'WBS - Updated Product Backlog'!$D$19&"" -> 2.2.3 Filter and sort by distance, rating and availability | Y29: ='WBS - Updated Product Backlog'!$J$19 -> 7 | AA29: ='WBS - Updated Product Backlog'!$C$6&" "&'WBS - Updated Product Backlog'!$D$6&"" -> 1.2.1 Build customer profile page | AE29: ='WBS - Updated Product Backlog'!$H$6 -> 4
B30: ='WBS - Updated Product Backlog'!$C$56&" "&'WBS - Updated Product Backlog'!$D$56&"" -> 5.2.3 Integrate all five modules with shared navigation and API contracts | G30: ='WBS - Updated Product Backlog'!$P$56 -> 7 | I30: ='WBS - Updated Product Backlog'!$C$43&" "&'WBS - Updated Product Backlog'!$D$43&"" -> 4.2.3 Build admin complaint and safety-review queue | M30: ='WBS - Updated Product Backlog'!$N$43 -> 7 | O30: ='WBS - Updated Product Backlog'!$C$29&" "&'WBS - Updated Product Backlog'!$D$29&"" -> 3.2.1 Build technician incoming-request queue | S30: ='WBS - Updated Product Backlog'!$L$29 -> 5 | U30: ='WBS - Updated Product Backlog'!$C$20&" "&'WBS - Updated Product Backlog'!$D$20&"" -> 2.2.4 Build map/list results with technician profile links | Y30: ='WBS - Updated Product Backlog'!$J$20 -> 9 | AA30: ='WBS - Updated Product Backlog'!$C$7&" "&'WBS - Updated Product Backlog'!$D$7&"" -> 1.2.2 Implement profile update functionality | AE30: ='WBS - Updated Product Backlog'!$H$7 -> 5
B31: ='WBS - Updated Product Backlog'!$C$57&" "&'WBS - Updated Product Backlog'!$D$57&"" -> 5.2.4 Run end-to-end integration and smoke tests | G31: ='WBS - Updated Product Backlog'!$P$57 -> 7 | I31: ='WBS - Updated Product Backlog'!$C$44&" "&'WBS - Updated Product Backlog'!$D$44&"" -> 4.2.4 Record action, resolution and complaint status | M31: ='WBS - Updated Product Backlog'!$N$44 -> 8 | O31: ='WBS - Updated Product Backlog'!$C$30&" "&'WBS - Updated Product Backlog'!$D$30&"" -> 3.2.2 Implement accept/reject response workflow | S31: ='WBS - Updated Product Backlog'!$L$30 -> 6 | U31: ='WBS - Updated Product Backlog'!$C$21&" "&'WBS - Updated Product Backlog'!$D$21&"" -> 2.3.1 Handle location-permission and map/API errors | Y31: ='WBS - Updated Product Backlog'!$J$21 -> 5 | AA31: ='WBS - Updated Product Backlog'!$C$8&" "&'WBS - Updated Product Backlog'!$D$8&"" -> 1.2.3 Implement forgot-password and password-reset flow | AE31: ='WBS - Updated Product Backlog'!$H$8 -> 5
B32: ='WBS - Updated Product Backlog'!$C$58&" "&'WBS - Updated Product Backlog'!$D$58&"" -> 5.3.1 Prepare and execute user-acceptance test cases | G32: ='WBS - Updated Product Backlog'!$P$58 -> 7 | I32: ='WBS - Updated Product Backlog'!$C$45&" "&'WBS - Updated Product Backlog'!$D$45&"" -> 4.3.1 Flag abusive, fake or duplicate review candidates using basic rules | M32: ='WBS - Updated Product Backlog'!$N$45 -> 6 | O32: ='WBS - Updated Product Backlog'!$C$31&" "&'WBS - Updated Product Backlog'!$D$31&"" -> 3.2.3 Send customer confirmation and request notification | S32: ='WBS - Updated Product Backlog'!$L$31 -> 7 | U32: ='WBS - Updated Product Backlog'!$C$22&" "&'WBS - Updated Product Backlog'!$D$22&"" -> 2.3.2 Implement area/service fallback when map results fail | Y32: ='WBS - Updated Product Backlog'!$J$22 -> 6 | AA32: ='WBS - Updated Product Backlog'!$C$9&" "&'WBS - Updated Product Backlog'!$D$9&"" -> 1.2.4 Apply customer, technician and admin role-based access | AE32: ='WBS - Updated Product Backlog'!$H$9 -> 6
B33: ='WBS - Updated Product Backlog'!$C$59&" "&'WBS - Updated Product Backlog'!$D$59&"" -> 5.3.2 Fix critical defects and run regression tests | G33: ='WBS - Updated Product Backlog'!$P$59 -> 7 | I33: ='WBS - Updated Product Backlog'!$C$46&" "&'WBS - Updated Product Backlog'!$D$46&"" -> 4.3.2 Allow admin to hide or restore inappropriate reviews | M33: ='WBS - Updated Product Backlog'!$N$46 -> 6 | O33: ='WBS - Updated Product Backlog'!$C$32&" "&'WBS - Updated Product Backlog'!$D$32&"" -> 3.3.1 Implement request status transitions from sent to completed | S33: ='WBS - Updated Product Backlog'!$L$32 -> 7 | U33: ='WBS - Updated Product Backlog'!$C$23&" "&'WBS - Updated Product Backlog'!$D$23&"" -> 2.3.3 Test multiple Dhaka locations, empty states and edge cases | Y33: ='WBS - Updated Product Backlog'!$J$23 -> 5 | AA33: ='WBS - Updated Product Backlog'!$C$10&" "&'WBS - Updated Product Backlog'!$D$10&"" -> 1.3.1 Create technician service-category and working-area form | AE33: ='WBS - Updated Product Backlog'!$H$10 -> 5
B34: ='WBS - Updated Product Backlog'!$C$60&" "&'WBS - Updated Product Backlog'!$D$60&"" -> 5.3.3 Verify security, roles and technician-verification controls | G34: ='WBS - Updated Product Backlog'!$P$60 -> 5 | I34: ='WBS - Updated Product Backlog'!$C$47&" "&'WBS - Updated Product Backlog'!$D$47&"" -> 4.3.3 Show verified-service indicator on eligible reviews | M34: ='WBS - Updated Product Backlog'!$N$47 -> 4 | O34: ='WBS - Updated Product Backlog'!$C$33&" "&'WBS - Updated Product Backlog'!$D$33&"" -> 3.3.2 Build customer status timeline and tracking view | S34: ='WBS - Updated Product Backlog'!$L$33 -> 5 | U34: ='WBS - Updated Product Backlog'!$C$24&" "&'WBS - Updated Product Backlog'!$D$24&"" -> 2.3.4 Limit and handle stored location data safely | Y34: ='WBS - Updated Product Backlog'!$J$24 -> 4 | AA34: ='WBS - Updated Product Backlog'!$C$12&" "&'WBS - Updated Product Backlog'!$D$12&"" -> 1.3.3 Build admin approve/reject verification workflow | AE34: ='WBS - Updated Product Backlog'!$H$12 -> 6
B35: ='WBS - Updated Product Backlog'!$C$61&" "&'WBS - Updated Product Backlog'!$D$61&"" -> 5.3.4 Configure demo deployment, domain and SSL | G35: ='WBS - Updated Product Backlog'!$P$61 -> 5 | I35: ='WBS - Updated Product Backlog'!$C$48&" "&'WBS - Updated Product Backlog'!$D$48&"" -> 4.3.4 Run rating, complaint and moderation workflow tests | M35: ='WBS - Updated Product Backlog'!$N$48 -> 4 | O35: ='WBS - Updated Product Backlog'!$C$34&" "&'WBS - Updated Product Backlog'!$D$34&"" -> 3.3.3 Add controlled emergency/urgent request flag | S35: ='WBS - Updated Product Backlog'!$L$34 -> 6 | AA35: ='WBS - Updated Product Backlog'!$C$13&" "&'WBS - Updated Product Backlog'!$D$13&"" -> 1.3.4 Show verification status and verified badge | AE35: ='WBS - Updated Product Backlog'!$H$13 -> 4
B36: ='WBS - Updated Product Backlog'!$C$62&" "&'WBS - Updated Product Backlog'!$D$62&"" -> 5.3.5 Complete final documentation, demonstration and handover | G36: ='WBS - Updated Product Backlog'!$P$62 -> 6 | I36: ='WBS - Updated Product Backlog'!$C$49&" "&'WBS - Updated Product Backlog'!$D$49&"" -> 5.1.1 Build admin dashboard summary | M36: ='WBS - Updated Product Backlog'!$N$49 -> 5 | O36: ='WBS - Updated Product Backlog'!$C$35&" "&'WBS - Updated Product Backlog'!$D$35&"" -> 3.3.4 Display estimated price/time and booking confirmation | S36: ='WBS - Updated Product Backlog'!$L$35 -> 6 | AA36: ='WBS - Updated Product Backlog'!$C$14&" "&'WBS - Updated Product Backlog'!$D$14&"" -> 2.1.1 Request browser location permission and capture coordinates | AE36: ='WBS - Updated Product Backlog'!$H$14 -> 5
I37: ='WBS - Updated Product Backlog'!$C$50&" "&'WBS - Updated Product Backlog'!$D$50&"" -> 5.1.2 Search and view customers, technicians and service requests | M37: ='WBS - Updated Product Backlog'!$N$50 -> 5 | O37: ='WBS - Updated Product Backlog'!$C$36&" "&'WBS - Updated Product Backlog'!$D$36&"" -> 3.3.5 Notify users about important request-status changes | S37: ='WBS - Updated Product Backlog'!$L$36 -> 6
O38: ='WBS - Updated Product Backlog'!$C$37&" "&'WBS - Updated Product Backlog'!$D$37&"" -> 4.1.1 Enable rating only after a completed service | S38: ='WBS - Updated Product Backlog'!$L$37 -> 5
B39: Grand Total | C39: Grand Total | D39: Grand Total | E39: Grand Total | F39: Grand Total | G39: =SUM(G25:G38) -> 70 | I39: Grand Total | J39: Grand Total | K39: Grand Total | L39: Grand Total | M39: =SUM(M25:M38) -> 70 | O39: Grand Total | P39: Grand Total | Q39: Grand Total | R39: Grand Total | S39: =SUM(S25:S38) -> 80 | U39: Grand Total | V39: Grand Total | W39: Grand Total | X39: Grand Total | Y39: =SUM(Y25:Y38) -> 68 | AA39: Grand Total | AB39: Grand Total | AC39: Grand Total | AD39: Grand Total | AE39: =SUM(AE25:AE38) -> 62

Sheet Pivot
A1: FixBondhu - Module, Sprint and Cost Summary | 5 Sprints | B1: FixBondhu - Module, Sprint and Cost Summary | 5 Sprints | C1: FixBondhu - Module, Sprint and Cost Summary | 5 Sprints | D1: FixBondhu - Module, Sprint and Cost Summary | 5 Sprints | E1: FixBondhu - Module, Sprint and Cost Summary | 5 Sprints | F1: FixBondhu - Module, Sprint and Cost Summary | 5 Sprints | G1: FixBondhu - Module, Sprint and Cost Summary | 5 Sprints | H1: FixBondhu - Module, Sprint and Cost Summary | 5 Sprints | I1: FixBondhu - Module, Sprint and Cost Summary | 5 Sprints | J1: FixBondhu - Module, Sprint and Cost Summary | 5 Sprints | K1: FixBondhu - Module, Sprint and Cost Summary | 5 Sprints | L1: FixBondhu - Module, Sprint and Cost Summary | 5 Sprints
A2: Sprints 1 and 2 are behind schedule; Sprints 3, 4 and 5 are on schedule. Sprint 5 closes all 350 story points. | B2: Sprints 1 and 2 are behind schedule; Sprints 3, 4 and 5 are on schedule. Sprint 5 closes all 350 story points. | C2: Sprints 1 and 2 are behind schedule; Sprints 3, 4 and 5 are on schedule. Sprint 5 closes all 350 story points. | D2: Sprints 1 and 2 are behind schedule; Sprints 3, 4 and 5 are on schedule. Sprint 5 closes all 350 story points. | E2: Sprints 1 and 2 are behind schedule; Sprints 3, 4 and 5 are on schedule. Sprint 5 closes all 350 story points. | F2: Sprints 1 and 2 are behind schedule; Sprints 3, 4 and 5 are on schedule. Sprint 5 closes all 350 story points. | G2: Sprints 1 and 2 are behind schedule; Sprints 3, 4 and 5 are on schedule. Sprint 5 closes all 350 story points. | H2: Sprints 1 and 2 are behind schedule; Sprints 3, 4 and 5 are on schedule. Sprint 5 closes all 350 story points. | I2: Sprints 1 and 2 are behind schedule; Sprints 3, 4 and 5 are on schedule. Sprint 5 closes all 350 story points. | J2: Sprints 1 and 2 are behind schedule; Sprints 3, 4 and 5 are on schedule. Sprint 5 closes all 350 story points. | K2: Sprints 1 and 2 are behind schedule; Sprints 3, 4 and 5 are on schedule. Sprint 5 closes all 350 story points. | L2: Sprints 1 and 2 are behind schedule; Sprints 3, 4 and 5 are on schedule. Sprint 5 closes all 350 story points.
A4: Labor Cost (BDT) | B4: Labor Cost (BDT) | C4: Direct Cost (BDT) | D4: Direct Cost (BDT) | E4: Contingency (BDT) | F4: Contingency (BDT) | G4: COST BASELINE (BDT) | H4: COST BASELINE (BDT) | I4: COST BASELINE (BDT) | J4: Total Story Points | K4: Total Story Points | L4: Total Story Points
A5: ='Sprint wise spent'!$F$12 -> 207800 | C5: =Config!$D$22 -> 23000 | E5: ='Risk & Opportunity'!$D$5 -> 20040 | G5: =SUM(A5,C5,E5) -> 250840 | J5: ='WBS - Updated Product Backlog'!$E$63 -> 350
A8: Module-wise Estimation | B8: Module-wise Estimation | D8: Sprint-wise Delivery and Cost Baseline | E8: Sprint-wise Delivery and Cost Baseline | F8: Sprint-wise Delivery and Cost Baseline | G8: Sprint-wise Delivery and Cost Baseline | H8: Sprint-wise Delivery and Cost Baseline | J8: Risk / Opportunity Summary | K8: Risk / Opportunity Summary | L8: Risk / Opportunity Summary
A9: Module | B9: Story Points | D9: Sprint | E9: Start | F9: End | G9: Planned Points | H9: Cost Baseline (BDT) | J9: Measure | K9: Measure | L9: BDT
A10: 1. Accounts & Verification | B10: =SUM('WBS - Updated Product Backlog'!$E$2:$E$13) -> 65 | D10: 1 | E10: =Config!$B$6+(1-1)*Config!$B$10 -> 46230 | F10: =E10+Config!$B$10-1 -> 46243 | G10: =SUMIF('WBS - Updated Product Backlog'!$F$2:$F$62,D10,'WBS - Updated Product Backlog'!$E$2:$E$62) -> 70 | H10: ='Sprint wise spent'!$AD$11*Config!$B$12+SUMIF(Config!$C$17:$C$21,D10,Config!$D$17:$D$21)+SUMIF('Risk & Opportunity'!$E$8:$E$15,D10,'Risk & Opportunity'!$L$8:$L$15) -> 45090 | J10: Threat EMV before response | K10: Threat EMV before response | L10: ='Risk & Opportunity'!$A$5 -> 43690
A11: 2. Location-Based Discovery | B11: =SUM('WBS - Updated Product Backlog'!$E$14:$E$24) -> 70 | D11: 2 | E11: =Config!$B$6+(2-1)*Config!$B$10 -> 46244 | F11: =E11+Config!$B$10-1 -> 46257 | G11: =SUMIF('WBS - Updated Product Backlog'!$F$2:$F$62,D11,'WBS - Updated Product Backlog'!$E$2:$E$62) -> 70 | H11: ='Sprint wise spent'!$X$11*Config!$B$12+SUMIF(Config!$C$17:$C$21,D11,Config!$D$17:$D$21)+SUMIF('Risk & Opportunity'!$E$8:$E$15,D11,'Risk & Opportunity'!$L$8:$L$15) -> 55640 | J11: Residual threat EMV / contingency | K11: Residual threat EMV / contingency | L11: ='Risk & Opportunity'!$D$5 -> 20040
A12: 3. Service Request, Booking & Tracking | B12: =SUM('WBS - Updated Product Backlog'!$E$25:$E$36) -> 70 | D12: 3 | E12: =Config!$B$6+(3-1)*Config!$B$10 -> 46258 | F12: =E12+Config!$B$10-1 -> 46271 | G12: =SUMIF('WBS - Updated Product Backlog'!$F$2:$F$62,D12,'WBS - Updated Product Backlog'!$E$2:$E$62) -> 70 | H12: ='Sprint wise spent'!$R$11*Config!$B$12+SUMIF(Config!$C$17:$C$21,D12,Config!$D$17:$D$21)+SUMIF('Risk & Opportunity'!$E$8:$E$15,D12,'Risk & Opportunity'!$L$8:$L$15) -> 41800 | J12: Opportunity EMV before action | K12: Opportunity EMV before action | L12: ='Risk & Opportunity'!$G$5 -> 22170
A13: 4. Trust, Safety & Feedback | B13: =SUM('WBS - Updated Product Backlog'!$E$37:$E$48) -> 65 | D13: 4 | E13: =Config!$B$6+(4-1)*Config!$B$10 -> 46272 | F13: =E13+Config!$B$10-1 -> 46285 | G13: =SUMIF('WBS - Updated Product Backlog'!$F$2:$F$62,D13,'WBS - Updated Product Backlog'!$E$2:$E$62) -> 70 | H13: ='Sprint wise spent'!$L$11*Config!$B$12+SUMIF(Config!$C$17:$C$21,D13,Config!$D$17:$D$21)+SUMIF('Risk & Opportunity'!$E$8:$E$15,D13,'Risk & Opportunity'!$L$8:$L$15) -> 40790 | J13: Post-action opportunity EMV | K13: Post-action opportunity EMV | L13: ='Risk & Opportunity'!$J$5 -> 30230
A14: 5. Admin & Platform Management | B14: =SUM('WBS - Updated Product Backlog'!$E$49:$E$62) -> 80 | D14: 5 | E14: =Config!$B$6+(5-1)*Config!$B$10 -> 46286 | F14: =E14+Config!$B$10-1 -> 46299 | G14: =SUMIF('WBS - Updated Product Backlog'!$F$2:$F$62,D14,'WBS - Updated Product Backlog'!$E$2:$E$62) -> 70 | H14: ='Sprint wise spent'!$F$11*Config!$B$12+SUMIF(Config!$C$17:$C$21,D14,Config!$D$17:$D$21)+SUMIF('Risk & Opportunity'!$E$8:$E$15,D14,'Risk & Opportunity'!$L$8:$L$15) -> 67520
A15: Grand Total | B15: =SUM(B10:B14) -> 350 | D15: Grand Total | E15: Grand Total | F15: Grand Total | G15: =SUM(G10:G14) -> 350 | H15: =SUM(H10:H14) -> 250840
A18: Schedule and Earned Value Tracking Summary | B18: Schedule and Earned Value Tracking Summary | C18: Schedule and Earned Value Tracking Summary | D18: Schedule and Earned Value Tracking Summary | E18: Schedule and Earned Value Tracking Summary | F18: Schedule and Earned Value Tracking Summary | G18: Schedule and Earned Value Tracking Summary | H18: Schedule and Earned Value Tracking Summary | I18: Schedule and Earned Value Tracking Summary | J18: Reconciliation Checks | K18: Reconciliation Checks | L18: Reconciliation Checks
A19: Sprint | B19: Done Points | C19: Cum. Done | D19: Cum. Planned | E19: SV (Points) | F19: Cum. EV (BDT) | G19: Cum. PV (BDT) | H19: SV (BDT) | I19: Status | J19: Baseline - Labor - Direct - Contingency | K19: Baseline - Labor - Direct - Contingency | L19: =G5-A5-C5-E5 -> 0
A20: 1 | B20: ='WBS - Updated Product Backlog'!$H$63 -> 62 | C20: =B20 -> 62 | D20: =G10 -> 70 | E20: =C20-D20 -> -8 | F20: =C20/$J$5*$G$5 -> 44434.514 | G20: =D20/$J$5*$G$5 -> 50168 | H20: =F20-G20 -> -5733.4857 | I20: =IF(E20=0,"On Schedule",IF(E20<0,"Behind Schedule","Ahead of Schedule")) -> Behind Schedule | J20: Final Remaining Story Points | K20: Final Remaining Story Points | L20: ='WBS - Updated Product Backlog'!$Q$63 -> 0
A21: 2 | B21: ='WBS - Updated Product Backlog'!$J$63 -> 68 | C21: =C20+B21 -> 130 | D21: =D20+G11 -> 140 | E21: =C21-D21 -> -10 | F21: =C21/$J$5*$G$5 -> 93169.143 | G21: =D21/$J$5*$G$5 -> 100336 | H21: =F21-G21 -> -7166.8571 | I21: =IF(E21=0,"On Schedule",IF(E21<0,"Behind Schedule","Ahead of Schedule")) -> Behind Schedule | J21: Sprint Baseline Total - Project Baseline | K21: Sprint Baseline Total - Project Baseline | L21: =H15-G5 -> 0
A22: 3 | B22: ='WBS - Updated Product Backlog'!$L$63 -> 80 | C22: =C21+B22 -> 210 | D22: =D21+G12 -> 210 | E22: =C22-D22 -> 0 | F22: =C22/$J$5*$G$5 -> 150504 | G22: =D22/$J$5*$G$5 -> 150504 | H22: =F22-G22 -> 0 | I22: =IF(E22=0,"On Schedule",IF(E22<0,"Behind Schedule","Ahead of Schedule")) -> On Schedule | J22: Five-sprint Story Points - Total Story Points | K22: Five-sprint Story Points - Total Story Points | L22: =G15-J5 -> 0
A23: 4 | B23: ='WBS - Updated Product Backlog'!$N$63 -> 70 | C23: =C22+B23 -> 280 | D23: =D22+G13 -> 280 | E23: =C23-D23 -> 0 | F23: =C23/$J$5*$G$5 -> 200672 | G23: =D23/$J$5*$G$5 -> 200672 | H23: =F23-G23 -> 0 | I23: =IF(E23=0,"On Schedule",IF(E23<0,"Behind Schedule","Ahead of Schedule")) -> On Schedule | J23: Total Done Points - Total Story Points | K23: Total Done Points - Total Story Points | L23: =SUM(B20:B24)-J5 -> 0
A24: 5 | B24: ='WBS - Updated Product Backlog'!$P$63 -> 70 | C24: =C23+B24 -> 350 | D24: =D23+G14 -> 350 | E24: =C24-D24 -> 0 | F24: =C24/$J$5*$G$5 -> 250840 | G24: =D24/$J$5*$G$5 -> 250840 | H24: =F24-G24 -> 0 | I24: =IF(E24=0,"On Schedule",IF(E24<0,"Behind Schedule","Ahead of Schedule")) -> On Schedule | J24: Final Schedule Variance (Points) | K24: Final Schedule Variance (Points) | L24: =E24 -> 0
J25: Behind Schedule Count - Required 2 | K25: Behind Schedule Count - Required 2 | L25: =COUNTIF(I20:I24,"Behind Schedule")-2 -> 0
J26: On Schedule Count - Required 3 | K26: On Schedule Count - Required 3 | L26: =COUNTIF(I20:I24,"On Schedule")-3 -> 0

Sheet Config
A1: FixBondhu - Configuration and Cost Assumptions | 5 Sprints | B1: FixBondhu - Configuration and Cost Assumptions | 5 Sprints | C1: FixBondhu - Configuration and Cost Assumptions | 5 Sprints | D1: FixBondhu - Configuration and Cost Assumptions | 5 Sprints | E1: FixBondhu - Configuration and Cost Assumptions | 5 Sprints | F1: FixBondhu - Configuration and Cost Assumptions | 5 Sprints | G1: FixBondhu - Configuration and Cost Assumptions | 5 Sprints | H1: FixBondhu - Configuration and Cost Assumptions | 5 Sprints | I1: FixBondhu - Configuration and Cost Assumptions | 5 Sprints | J1: FixBondhu - Configuration and Cost Assumptions | 5 Sprints | K1: FixBondhu - Configuration and Cost Assumptions | 5 Sprints
A2: Yellow cells are editable planning assumptions. Linked outputs update the WBS, sprint-cost, risk and Pivot sheets. | B2: Yellow cells are editable planning assumptions. Linked outputs update the WBS, sprint-cost, risk and Pivot sheets. | C2: Yellow cells are editable planning assumptions. Linked outputs update the WBS, sprint-cost, risk and Pivot sheets. | D2: Yellow cells are editable planning assumptions. Linked outputs update the WBS, sprint-cost, risk and Pivot sheets. | E2: Yellow cells are editable planning assumptions. Linked outputs update the WBS, sprint-cost, risk and Pivot sheets. | F2: Yellow cells are editable planning assumptions. Linked outputs update the WBS, sprint-cost, risk and Pivot sheets. | G2: Yellow cells are editable planning assumptions. Linked outputs update the WBS, sprint-cost, risk and Pivot sheets. | H2: Yellow cells are editable planning assumptions. Linked outputs update the WBS, sprint-cost, risk and Pivot sheets. | I2: Yellow cells are editable planning assumptions. Linked outputs update the WBS, sprint-cost, risk and Pivot sheets. | J2: Yellow cells are editable planning assumptions. Linked outputs update the WBS, sprint-cost, risk and Pivot sheets. | K2: Yellow cells are editable planning assumptions. Linked outputs update the WBS, sprint-cost, risk and Pivot sheets.
A4: Project Assumptions | B4: Project Assumptions | D4: Level / Weight | E4: Level / Weight | G4: Person | H4: Project Role | I4: Level | J4: Weight | K4: Day Rate (BDT)
A5: Project Name | B5: FixBondhu | D5: Junior | E5: 0.7 | G5: A | H5: Team Lead | I5: Lead | J5: =SUMIF($D$5:$D$8,I5,$E$5:$E$8) -> 2 | K5: =J5*$B$12 -> 4000
A6: Project Start | B6: 46230 | D6: Mid | E6: 1 | G6: B | H6: Backend Developer | I6: Senior | J6: =SUMIF($D$5:$D$8,I6,$E$5:$E$8) -> 1.3 | K6: =J6*$B$12 -> 2600
A7: Project Duration (calendar days) | B7: 70 | D7: Senior | E7: 1.3 | G7: C | H7: Frontend Developer | I7: Mid | J7: =SUMIF($D$5:$D$8,I7,$E$5:$E$8) -> 1 | K7: =J7*$B$12 -> 2000
A8: Project End | B8: =B6+B7-1 -> 46299 | D8: Lead | E8: 2 | G8: D | H8: QA / Tester | I8: Junior | J8: =SUMIF($D$5:$D$8,I8,$E$5:$E$8) -> 0.7 | K8: =J8*$B$12 -> 1400
A9: Sprint Count | B9: 5 | G9: E | H9: UI/UX Designer | I9: Mid | J9: =SUMIF($D$5:$D$8,I9,$E$5:$E$8) -> 1 | K9: =J9*$B$12 -> 2000
A10: Sprint Length (calendar days) | B10: 14
A11: Capacity / person / sprint (working days) | B11: 10
A12: Base Mid-level Rate (BDT/day) | B12: 2000
A13: Currency | B13: BDT
A15: Direct Non-Labor Cost Inputs | B15: Direct Non-Labor Cost Inputs | C15: Direct Non-Labor Cost Inputs | D15: Direct Non-Labor Cost Inputs | E15: Direct Non-Labor Cost Inputs | G15: Story-Point Estimation Scale Used in the Detailed WBS | H15: Story-Point Estimation Scale Used in the Detailed WBS | I15: Story-Point Estimation Scale Used in the Detailed WBS | J15: Story-Point Estimation Scale Used in the Detailed WBS | K15: Story-Point Estimation Scale Used in the Detailed WBS
A16: ID | B16: Cost Item | C16: Sprint # | D16: Amount (BDT) | E16: Why It Is Needed | G16: Points | H16: Meaning | I16: Meaning | J16: Meaning | K16: Meaning
A17: C1 | B17: Cloud development/deployment hosting | C17: 5 | D17: 8000 | E17: Staging and final demonstration hosting allowance. | G17: 4 | H17: Simple UI/configuration task | I17: Simple UI/configuration task | J17: Simple UI/configuration task | K17: Simple UI/configuration task
A18: C2 | B18: Map / location API testing | C18: 2 | D18: 6000 | E18: Geocoding and nearby-technician tests across several Dhaka locations. | G18: 5 | H18: Small work package with one clear logic path | I18: Small work package with one clear logic path | J18: Small work package with one clear logic path | K18: Small work package with one clear logic path
A19: C3 | B19: Domain and SSL | C19: 5 | D19: 2500 | E19: Public demo endpoint and secure HTTPS setup. | G19: 6 | H19: Medium workflow or validation task | I19: Medium workflow or validation task | J19: Medium workflow or validation task | K19: Medium workflow or validation task
A20: C4 | B20: Test devices, connectivity and test data | C20: 5 | D20: 4000 | E20: System/UAT testing under different devices and network conditions. | G20: 7 | H20: More complex workflow or integration task | I20: More complex workflow or integration task | J20: More complex workflow or integration task | K20: More complex workflow or integration task
A21: C5 | B21: Documentation, presentation and admin | C21: 5 | D21: 2500 | E21: Final documentation, handover and presentation-related expenses. | G21: 8 | H21: High-complexity API, security or data task | I21: High-complexity API, security or data task | J21: High-complexity API, security or data task | K21: High-complexity API, security or data task
A22: TOTAL DIRECT NON-LABOR COST | B22: TOTAL DIRECT NON-LABOR COST | C22: TOTAL DIRECT NON-LABOR COST | D22: =SUM(D17:D21) -> 23000 | E22: Must reconcile to the cost baseline summary. | G22: 9 | H22: Most complex map/results or cross-component task | I22: Most complex map/results or cross-component task | J22: Most complex map/results or cross-component task | K22: Most complex map/results or cross-component task
A24: Method and Source Notes | B24: Method and Source Notes | C24: Method and Source Notes | D24: Method and Source Notes | E24: Method and Source Notes | F24: Method and Source Notes | G24: Method and Source Notes | H24: Method and Source Notes | I24: Method and Source Notes | J24: Method and Source Notes | K24: Method and Source Notes
A25: Cost baseline formula | B25: Cost baseline formula | C25: Labor cost + direct non-labor cost + residual threat EMV contingency. | D25: Labor cost + direct non-labor cost + residual threat EMV contingency. | E25: Labor cost + direct non-labor cost + residual threat EMV contingency. | F25: Labor cost + direct non-labor cost + residual threat EMV contingency. | G25: Labor cost + direct non-labor cost + residual threat EMV contingency. | H25: Labor cost + direct non-labor cost + residual threat EMV contingency. | I25: Labor cost + direct non-labor cost + residual threat EMV contingency. | J25: Labor cost + direct non-labor cost + residual threat EMV contingency. | K25: Labor cost + direct non-labor cost + residual threat EMV contingency.
A26: Labor formula | B26: Labor formula | C26: Weighted man-days x BDT 2,000; weighted allocation uses the instructor level weights. | D26: Weighted man-days x BDT 2,000; weighted allocation uses the instructor level weights. | E26: Weighted man-days x BDT 2,000; weighted allocation uses the instructor level weights. | F26: Weighted man-days x BDT 2,000; weighted allocation uses the instructor level weights. | G26: Weighted man-days x BDT 2,000; weighted allocation uses the instructor level weights. | H26: Weighted man-days x BDT 2,000; weighted allocation uses the instructor level weights. | I26: Weighted man-days x BDT 2,000; weighted allocation uses the instructor level weights. | J26: Weighted man-days x BDT 2,000; weighted allocation uses the instructor level weights. | K26: Weighted man-days x BDT 2,000; weighted allocation uses the instructor level weights.
A27: Contingency rule | B27: Contingency rule | C27: Only post-response Threat EMV is added to the baseline. Opportunity savings remain separate until achieved. | D27: Only post-response Threat EMV is added to the baseline. Opportunity savings remain separate until achieved. | E27: Only post-response Threat EMV is added to the baseline. Opportunity savings remain separate until achieved. | F27: Only post-response Threat EMV is added to the baseline. Opportunity savings remain separate until achieved. | G27: Only post-response Threat EMV is added to the baseline. Opportunity savings remain separate until achieved. | H27: Only post-response Threat EMV is added to the baseline. Opportunity savings remain separate until achieved. | I27: Only post-response Threat EMV is added to the baseline. Opportunity savings remain separate until achieved. | J27: Only post-response Threat EMV is added to the baseline. Opportunity savings remain separate until achieved. | K27: Only post-response Threat EMV is added to the baseline. Opportunity savings remain separate until achieved.
A28: Team-role mapping | B28: Team-role mapping | C28: The five names come from the FixBondhu presentation. Roles and levels remain editable. | D28: The five names come from the FixBondhu presentation. Roles and levels remain editable. | E28: The five names come from the FixBondhu presentation. Roles and levels remain editable. | F28: The five names come from the FixBondhu presentation. Roles and levels remain editable. | G28: The five names come from the FixBondhu presentation. Roles and levels remain editable. | H28: The five names come from the FixBondhu presentation. Roles and levels remain editable. | I28: The five names come from the FixBondhu presentation. Roles and levels remain editable. | J28: The five names come from the FixBondhu presentation. Roles and levels remain editable. | K28: The five names come from the FixBondhu presentation. Roles and levels remain editable.
A29: Schedule source | B29: Schedule source | C29: Updated five-sprint plan: 27 Jul 2026 to 04 Oct 2026, 70 calendar days, five two-week sprints. | D29: Updated five-sprint plan: 27 Jul 2026 to 04 Oct 2026, 70 calendar days, five two-week sprints. | E29: Updated five-sprint plan: 27 Jul 2026 to 04 Oct 2026, 70 calendar days, five two-week sprints. | F29: Updated five-sprint plan: 27 Jul 2026 to 04 Oct 2026, 70 calendar days, five two-week sprints. | G29: Updated five-sprint plan: 27 Jul 2026 to 04 Oct 2026, 70 calendar days, five two-week sprints. | H29: Updated five-sprint plan: 27 Jul 2026 to 04 Oct 2026, 70 calendar days, five two-week sprints. | I29: Updated five-sprint plan: 27 Jul 2026 to 04 Oct 2026, 70 calendar days, five two-week sprints. | J29: Updated five-sprint plan: 27 Jul 2026 to 04 Oct 2026, 70 calendar days, five two-week sprints. | K29: Updated five-sprint plan: 27 Jul 2026 to 04 Oct 2026, 70 calendar days, five two-week sprints.
A30: Instructor reference | B30: Instructor reference | C30: Instructor sample weights: Junior 0.7, Mid 1.0, Senior 1.3 and Lead 2.0. | D30: Instructor sample weights: Junior 0.7, Mid 1.0, Senior 1.3 and Lead 2.0. | E30: Instructor sample weights: Junior 0.7, Mid 1.0, Senior 1.3 and Lead 2.0. | F30: Instructor sample weights: Junior 0.7, Mid 1.0, Senior 1.3 and Lead 2.0. | G30: Instructor sample weights: Junior 0.7, Mid 1.0, Senior 1.3 and Lead 2.0. | H30: Instructor sample weights: Junior 0.7, Mid 1.0, Senior 1.3 and Lead 2.0. | I30: Instructor sample weights: Junior 0.7, Mid 1.0, Senior 1.3 and Lead 2.0. | J30: Instructor sample weights: Junior 0.7, Mid 1.0, Senior 1.3 and Lead 2.0. | K30: Instructor sample weights: Junior 0.7, Mid 1.0, Senior 1.3 and Lead 2.0.
A31: Progress scenario | B31: Progress scenario | C31: Done by sprint: 62, 68, 80, 70, 70. Cumulative SV: -8, -10, 0, 0, 0. Sprints 1-2 are behind; Sprints 3-5 are on schedule. | D31: Done by sprint: 62, 68, 80, 70, 70. Cumulative SV: -8, -10, 0, 0, 0. Sprints 1-2 are behind; Sprints 3-5 are on schedule. | E31: Done by sprint: 62, 68, 80, 70, 70. Cumulative SV: -8, -10, 0, 0, 0. Sprints 1-2 are behind; Sprints 3-5 are on schedule. | F31: Done by sprint: 62, 68, 80, 70, 70. Cumulative SV: -8, -10, 0, 0, 0. Sprints 1-2 are behind; Sprints 3-5 are on schedule. | G31: Done by sprint: 62, 68, 80, 70, 70. Cumulative SV: -8, -10, 0, 0, 0. Sprints 1-2 are behind; Sprints 3-5 are on schedule. | H31: Done by sprint: 62, 68, 80, 70, 70. Cumulative SV: -8, -10, 0, 0, 0. Sprints 1-2 are behind; Sprints 3-5 are on schedule. | I31: Done by sprint: 62, 68, 80, 70, 70. Cumulative SV: -8, -10, 0, 0, 0. Sprints 1-2 are behind; Sprints 3-5 are on schedule. | J31: Done by sprint: 62, 68, 80, 70, 70. Cumulative SV: -8, -10, 0, 0, 0. Sprints 1-2 are behind; Sprints 3-5 are on schedule. | K31: Done by sprint: 62, 68, 80, 70, 70. Cumulative SV: -8, -10, 0, 0, 0. Sprints 1-2 are behind; Sprints 3-5 are on schedule.

Sheet Risk & Opportunity
